Workbook

Sheet READ.ME
A1: File | B1: Purpose | C1: Granularity | D1: Key columns
A2: feed_intake_raw.csv | B2: Cleaned feed-intake observations after unit harmonisation. | C2: One row per study × diet (only “Entire Diet” rows). | D2: B.Code, A.Level.Name, feed_intake_value (kg DM day⁻¹), bw_kg, adg_g_day, milk_kg_day, plus all *_nutrition and *_digest variables
A3: feed_intake_summary.csv | B3: High-level snapshot of performance metrics. | C3: One row per Species × P.Practice. | D3: Species, P.Practice, n_obs, mean ± SD for FI, BW, ADG, Milk
A4: variable_coverage_summary.csv | B4: Completeness audit. | C4: One row per variable. | D4: Variable, Coverage_% (0-100 %)
A5: feed_intake_raw_variables | B5: metadata of feed_intake_raw
A6: feed_intake_summary_variables | B6: metdata of feed_intake_summary

Sheet feed_intake_summary_variables
A1: Column | B1: What it represents (unit/notes)
A2: Species | B2: Animal species (e.g., cattle, goat, camel) that the diets belong to.
A3: P.Practice | B3: Breed categorization (imporved, unimproved)
A4: n_obs | B4: Number of diet records (A.Level.Name) that contribute to the summary for this Species × Practice combination.
A5: feed_intake_mean | B5: Mean daily feed (dry-matter) intake per animal, kg DM day⁻¹.
A6: feed_intake_sd | B6: Sample standard deviation (SD) of daily feed-intake for those diets, same unit as the mean.
A7: bw_kg_mean | B7: Mean starting body-weight, kg.
A8: bw_kg_sd | B8: SD of starting body-weight, kg.
A9: adg_g_day_mean | B9: Mean average daily gain (growth rate), g day⁻¹.
A10: adg_g_day_sd | B10: SD of average daily gain, g day⁻¹.
A11: milk_kg_day_mean | B11: Mean milk yield, kg day⁻¹ (NA or blank for non-lactating classes).
A12: milk_kg_day_sd | B12: SD of milk yield, kg day⁻¹ (NA if milk not recorded).

Sheet feed_intake_raw_variables
A1: Column | B1: What it represents (unit/notes)
A2: B.Code | B2: Unique study or “batch” identifier in the Digital Atlas database
A3: A.Level.Name | B3: Diet or treatment level within the study (often identical to D.Item)
A4: feed_intake_unit | B4: Unit string for feed-intake values (always kg DM day⁻¹ after harmonisation)
A5: feed_intake_value | B5: Daily dry-matter intake per animal
A6: feed_intake_error | B6: Reported error term (SD or SE, depending on study)
A7: bw_kg | B7: Mean starting body-weight (kg)
A8: adg_g_day | B8: Average daily gain (g day⁻¹)
A9: milk_kg_day | B9: Milk yield (kg day⁻¹) if recorded (NA for growing animals)
A10: T.Animals | B10: Number of animals in the treatment group
A11: Species | B11: Animal species (cow, goat, camel, …)
A12: Variety | B12: Breed, genetic line or cultivar (if provided)
... A81: NE_digest | B81: Net energy from digestibility (if present)

Sheet feed_intake_raw
A1: B.Code | B1: A.Level.Name | C1: feed_intake_unit | D1: feed_intake_value | E1: feed_intake_error | F1: bw_kg | G1: adg_kg_day | H1: milk_kg_day | I1: Sample.size | J1: Species | K1: Breed | L1: Breed.type.cattle | M1: Breed.type.sheep | N1: Breed.type.goat | O1: P.Practice | P1: Stage | Q1: Stage.harmonized | R1: production.system | S1: ADF_nutrition | T1: Ash_nutrition | U1: CP_nutrition | V1: DM_nutrition | W1: EE_nutrition | X1: NDF_nutrition | Y1: NDF_digest | Z1: ADL_nutrition | AA1: DM_digest | AB1: OM_digest | AC1: Feed.consumed.while.grazing? | AD1: marker.method | AE1: excluded
A2: AG0051 | B2: NG | C2: kg/day | D2: 8.3 | E2: NA | F2: NA | G2: NA | H2: 5.4 | I2: 10 | J2: Cattle | K2: Ankole Longhorn***Holstein Friesian | L2: =IF(OR(J2="Cattle",J2="Zebu Cattle"),IF(COUNTIF(lists!$M$2:$M$258, K2) > 0,"bos.indicus",IF(COUNTIF(lists!$L$2:$L$258, K2) > 0,"cross.bred","pure.bred.exotic")),"NA") -> cross.bred | O2: Hybridization or Cross Breeding | P2: NA | Q2: lactating.adult.female | R2: semi.intensive | S2: 372.6 | T2: 138.3 | U2: 124.5 | V2: 156.6 | W2: NA | X2: 386.3 | Y2: NA | Z2: NA | AA2: NA | AB2: NA | AC2: no | AD2: yes
A3: AG0051 | B3: NGD | C3: kg/day | D3: 8.2 | E3: NA | F3: NA | G3: NA | H3: 7.1 | I3: 10 | J3: Cattle | K3: Ankole Longhorn***Holstein Friesian | L3: =IF(OR(J3="Cattle",J3="Zebu Cattle"),IF(COUNTIF(lists!$M$2:$M$258, K3) > 0,"bos.indicus",IF(COUNTIF(lists!$L$2:$L$258, K3) > 0,"cross.bred","pure.bred.exotic")),"NA") -> cross.bred | O3: Hybridization or Cross Breeding | P3: NA | Q3: lactating.adult.female | R3: semi.intensive | S3: 300 | T3: 137.6 | U3: 153.1 | V3: 196.1 | W3: NA | X3: 431 | Y3: NA | Z3: NA | AA3: NA | AB3: NA | AC3: no | AD3: yes
A4: AG0051 | B4: PG | C4: kg/day | D4: 9.1 | E4: NA | F4: NA | G4: NA | H4: 8.1 | I4: 10 | J4: Cattle | K4: Ankole Longhorn***Holstein Friesian | L4: =IF(OR(J4="Cattle",J4="Zebu Cattle"),IF(COUNTIF(lists!$M$2:$M$258, K4) > 0,"bos.indicus",IF(COUNTIF(lists!$L$2:$L$258, K4) > 0,"cross.bred","pure.bred.exotic")),"NA") -> cross.bred | O4: Hybridization or Cross Breeding | P4: NA | Q4: lactating.adult.female | R4: semi.intensive | S4: 323.8 | T4: 117.7 | U4: 157.9 | V4: 238.5 | W4: NA | X4: 329.3 | Y4: NA | Z4: NA | AA4: NA | AB4: NA | AC4: no | AD4: yes
A5: AG0051 | B5: PGD | C5: kg/day | D5: 9.2 | E5: NA | F5: NA | G5: NA | H5: 9 | I5: 10 | J5: Cattle | K5: Ankole Longhorn***Holstein Friesian | L5: =IF(OR(J5="Cattle",J5="Zebu Cattle"),IF(COUNTIF(lists!$M$2:$M$258, K5) > 0,"bos.indicus",IF(COUNTIF(lists!$L$2:$L$258, K5) > 0,"cross.bred","pure.bred.exotic")),"NA") -> cross.bred | O5: Hybridization or Cross Breeding | P5: NA | Q5: lactating.adult.female | R5: semi.intensive | S5: 300.7 | T5: 127.2 | U5: 169.1 | V5: 241.4 | W5: NA | X5: 426.6 | Y5: NA | Z5: NA | AA5: NA | AB5: NA | AC5: no | AD5: yes
A6: BO1012 | B6: DLL0 | C6: kg/day | D6: 0.873 | E6: 11.4 | F6: NA | G6: NA | H6: NA | I6: 6 | J6: Sheep | K6: Unspecified | L6: =IF(OR(J6="Cattle",J6="Zebu Cattle"),IF(COUNTIF(lists!$M$2:$M$258, K6) > 0,"bos.indicus",IF(COUNTIF(lists!$L$2:$L$258, K6) > 0,"cross.bred","pure.bred.exotic")),"NA") -> NA | O6: Unspecified | P6: Yearling Male | Q6: growing.male | R6: intensive | S6: NA | T6: NA | U6: NA | V6: NA | W6: NA | X6: NA | Y6: NA | Z6: NA | AA6: NA | AB6: NA
A7: BO1012 | B7: DLL10 | C7: kg/day | D7: 0.861 | E7: 11.4 | F7: NA | G7: NA | H7: NA | I7: 6 | J7: Sheep | K7: Unspecified | L7: =IF(OR(J7="Cattle",J7="Zebu Cattle"),IF(COUNTIF(lists!$M$2:$M$258, K7) > 0,"bos.indicus",IF(COUNTIF(lists!$L$2:$L$258, K7) > 0,"cross.bred","pure.bred.exotic")),"NA") -> NA | O7: Unspecified | P7: Yearling Male | Q7: growing.male | R7: intensive | S7: NA | T7: NA | U7: NA | V7: NA | W7: NA | X7: NA | Y7: NA | Z7: NA | AA7: NA | AB7: NA
A8: BO1012 | B8: DLL15 | C8: kg/day | D8: 0.856 | E8: 11.4 | F8: NA | G8: NA | H8: NA | I8: 6 | J8: Sheep | K8: Unspecified | L8: =IF(OR(J8="Cattle",J8="Zebu Cattle"),IF(COUNTIF(lists!$M$2:$M$258, K8) > 0,"bos.indicus",IF(COUNTIF(lists!$L$2:$L$258, K8) > 0,"cross.bred","pure.bred.exotic")),"NA") -> NA | O8: Unspecified | P8: Yearling Male | Q8: growing.male | R8: intensive | S8: NA | T8: NA | U8: NA | V8: NA | W8: NA | X8: NA | Y8: NA | Z8: NA | AA8: NA | AB8: NA
A9: BO1012 | B9: DLL20 | C9: kg/day | D9: 0.839 | E9: 11.4 | F9: NA | G9: NA | H9: NA | I9: 6 | J9: Sheep | K9: Unspecified | L9: =IF(OR(J9="Cattle",J9="Zebu Cattle"),IF(COUNTIF(lists!$M$2:$M$258, K9) > 0,"bos.indicus",IF(COUNTIF(lists!$L$2:$L$258, K9) > 0,"cross.bred","pure.bred.exotic")),"NA") -> NA | O9: Unspecified | P9: Yearling Male | Q9: growing.male | R9: intensive | S9: NA | T9: NA | U9: NA | V9: NA | W9: NA | X9: NA | Y9: NA | Z9: NA | AA9: NA | AB9: NA
A10: BO1012 | B10: DLL5 | C10: kg/day | D10: 0.834 | E10: 11.4 | F10: NA | G10: NA | H10: NA | I10: 6 | J10: Sheep | K10: Unspecified | L10: =IF(OR(J10="Cattle",J10="Zebu Cattle"),IF(COUNTIF(lists!$M$2:$M$258, K10) > 0,"bos.indicus",IF(COUNTIF(lists!$L$2:$L$258, K10) > 0,"cross.bred","pure.bred.exotic")),"NA") -> NA | O10: Unspecified | P10: Yearling Male | Q10: growing.male | R10: intensive | S10: NA | T10: NA | U10: NA | V10: NA | W10: NA | X10: NA | Y10: NA | Z10: NA | AA10: NA | AB10: NA
A11: BO1023 | B11: CGS diet | C11: kg/day | D11: 13.43 | E11: 0.029 | F11: 404.71 | G11: NA | H11: 16.66 | I11: 9 | J11: Cattle | K11: Holstien_Friesian | L11: =IF(OR(J11="Cattle",J11="Zebu Cattle"),IF(COUNTIF(lists!$M$2:$M$258, K11) > 0,"bos.indicus",IF(COUNTIF(lists!$L$2:$L$258, K11) > 0,"cross.bred","pure.bred.exotic")),"NA") -> pure.bred.exotic | O11: Improved Breeds | P11: Lactating Female | Q11: lactating.adult.female | R11: intensive | S11: 254.8 | T11: NA | U11: 120.4 | V11: 586.3 | W11: 23.2 | X11: 377.4 | Y11: 65.36 | Z11: NA | AA11: 67.97 | AB11: 70.69 | AC11: no | AD11: yes
A12: BO1023 | B12: HSB diet | C12: kg/day | D12: 13.77 | E12: 0.029 | F12: 404.9 | G12: NA | H12: 17.05 | I12: 9 | J12: Cattle | K12: Holstien_Friesian | L12: =IF(OR(J12="Cattle",J12="Zebu Cattle"),IF(COUNTIF(lists!$M$2:$M$258, K12) > 0,"bos.indicus",IF(COUNTIF(lists!$L$2:$L$258, K12) > 0,"cross.bred","pure.bred.exotic")),"NA") -> pure.bred.exotic | O12: Improved Breeds | P12: Lactating Female | Q12: lactating.adult.female | R12: intensive | S12: 261.8 | T12: NA | U12: 122.7 | V12: 557.9 | W12: 22 | X12: 384.8 | Y12: 69.64 | Z12: NA | AA12: 68.61 | AB12: 72.61 | AC12: no | AD12: yes
A13: BO1023 | B13: LSB diet | C13: kg/day | D13: 13.66 | E13: 0.029 | F13: 405.22 | G13: NA | H13: 18 | I13: 9 | J13: Cattle | K13: Holstien_Friesian | L13: =IF(OR(J13="Cattle",J13="Zebu Cattle"),IF(COUNTIF(lists!$M$2:$M$258, K13) > 0,"bos.indicus",IF(COUNTIF(lists!$L$2:$L$258, K13) > 0,"cross.bred","pure.bred.exotic")),"NA") -> pure.bred.exotic | O13: Improved Breeds | P13: Lactating Female | Q13: lactating.adult.female | R13: intensive | S13: 258.4 | T13: NA | U13: 119.9 | V13: 568.6 | W13: 22.6 | X13: 384.8 | Y13: 67.93 | Z13: NA | AA13: 69.26 | AB13: 73.19 | AC13: no | AD13: yes
A14: BO1028 | B14: UMB + UTTS + concentrate | C14: kg/day | D14: 10.58 | E14: 19.03 | F14: 383.06 | G14: 0.28 | H14: 10.06 | I14: 10 | J14: Cattle | K14: Unspecified Crossbreed | L14: =IF(OR(J14="Cattle",J14="Zebu Cattle"),IF(COUNTIF(lists!$M$2:$M$258, K14) > 0,"bos.indicus",IF(COUNTIF(lists!$L$2:$L$258, K14) > 0,"cross.bred","pure.bred.exotic")),"NA") -> cross.bred | O14: NA | P14: Lactating Female | Q14: lactating.adult.female | R14: semi.intensive | S14: NA | T14: 61.3 | U14: 151.3 | V14: NA | W14: NA | X14: 502.5 | Y14: NA | Z14: NA | AA14: NA | AB14: NA | AC14: no | AD14: no
A15: BO1028 | B15: UTS + concentrate | C15: kg/day | D15: 10.18 | E15: 19.03 | F15: 291.03 | G15: 0.16 | H15: 9.61 | I15: 15 | J15: Cattle | K15: Unspecified Crossbreed | L15: =IF(OR(J15="Cattle",J15="Zebu Cattle"),IF(COUNTIF(lists!$M$2:$M$258, K15) > 0,"bos.indicus",IF(COUNTIF(lists!$L$2:$L$258, K15) > 0,"cross.bred","pure.bred.exotic")),"NA") -> cross.bred | O15: NA | P15: Lactating Female | Q15: lactating.adult.female | R15: semi.intensive | S15: NA | T15: NA | U15: NA | V15: NA | W15: NA | X15: NA | Y15: NA | Z15: NA | AA15: NA | AB15: NA | AC15: no | AD15: no
A16: BO1028 | B16: UTTS + concentrate | C16: kg/day | D16: 10.1 | E16: 19.03 | F16: 286.7 | G16: 0.02 | H16: 8.7 | I16: 15 | J16: Cattle | K16: Unspecified Crossbreed | L16: =IF(OR(J16="Cattle",J16="Zebu Cattle"),IF(COUNTIF(lists!$M$2:$M$258, K16) > 0,"bos.indicus",IF(COUNTIF(lists!$L$2:$L$258, K16) > 0,"cross.bred","pure.bred.exotic")),"NA") -> cross.bred | O16: NA | P16: Lactating Female | Q16: lactating.adult.female | R16: semi.intensive | S16: NA | T16: 70.7 | U16: 118.2 | V16: NA | W16: NA | X16: 552.4 | Y16: NA | Z16: NA | AA16: NA | AB16: NA | AC16: no | AD16: no
A17: BO1033 | B17: Melon seed husk 10 | C17: kg/day | D17: 5.81 | E17: 1.37 | F17: 134.7 | G17: 0.6 | H17: NA | I17: 3 | J17: Cattle | K17: Bunaji | L17: =IF(OR(J17="Cattle",J17="Zebu Cattle"),IF(COUNTIF(lists!$M$2:$M$258, K17) > 0,"bos.indicus",IF(COUNTIF(lists!$L$2:$L$258, K17) > 0,"cross.bred","pure.bred.exotic")),"NA") -> bos.indicus | O17: Unimproved Breed | P17: Bulls | Q17: growing.male | R17: intensive | S17: 331.8 | T17: 126.1 | U17: 179 | V17: 973.6 | W17: 41.9 | X17: 526.6 | Y17: NA | Z17: NA | AA17: NA | AB17: NA | AC17: no | AD17: no
A18: BO1033 | B18: Melon seed husk 20 | C18: kg/day | D18: 5.13 | E18: 1.37 | F18: 134 | G18: 0.69 | H18: NA | I18: 3 | J18: Cattle | K18: Bunaji | L18: =IF(OR(J18="Cattle",J18="Zebu Cattle"),IF(COUNTIF(lists!$M$2:$M$258, K18) > 0,"bos.indicus",IF(COUNTIF(lists!$L$2:$L$258, K18) > 0,"cross.bred","pure.bred.exotic")),"NA") -> bos.indicus | O18: Unimproved Breed | P18: Bulls | Q18: growing.male | R18: intensive | S18: 358.2 | T18: 89.8 | U18: 171.5 | V18: 976.9 | W18: 36.4 | X18: 568.6 | Y18: NA | Z18: NA | AA18: NA | AB18: NA | AC18: no | AD18: no
A19: BO1033 | B19: Melon seed husk 5 | C19: kg/day | D19: 5.03 | E19: 1.37 | F19: 133.7 | G19: 0.62 | H19: NA | I19: 3 | J19: Cattle | K19: Bunaji | L19: =IF(OR(J19="Cattle",J19="Zebu Cattle"),IF(COUNTIF(lists!$M$2:$M$258, K19) > 0,"bos.indicus",IF(COUNTIF(lists!$L$2:$L$258, K19) > 0,"cross.bred","pure.bred.exotic")),"NA") -> bos.indicus | O19: Unimproved Breed | P19: Bulls | Q19: growing.male | R19: intensive | S19: 327.5 | T19: 130.2 | U19: 182.1 | V19: 861 | W19: 46.9 | X19: 519.8 | Y19: NA | Z19: NA | AA19: NA | AB19: NA | AC19: no | AD19: no
A20: BO1033 | B20: Melon seek husk 0 | C20: kg/day | D20: 4.77 | E20: 1.37 | F20: 124.3 | G20: 0.57 | H20: NA | I20: 3 | J20: Cattle | K20: Bunaji | L20: =IF(OR(J20="Cattle",J20="Zebu Cattle"),IF(COUNTIF(lists!$M$2:$M$258, K20) > 0,"bos.indicus",IF(COUNTIF(lists!$L$2:$L$258, K20) > 0,"cross.bred","pure.bred.exotic")),"NA") -> bos.indicus | O20: Unimproved Breed | P20: Bulls | Q20: growing.male | R20: intensive | S20: 314.2 | T20: 139.4 | U20: 184.4 | V20: 875.7 | W20: 50.6 | X20: 498.8 | Y20: NA | Z20: NA | AA20: NA | AB20: NA | AC20: no | AD20: no
A21: BO1038 | B21: 0% treated rice offal | C21: kg/day | D21: 2.72 | E21: 0.45 | F21: 163.7 | G21: 0.23 | H21: NA | I21: 3 | J21: Cattle | K21: Bunaji | L21: =IF(OR(J21="Cattle",J21="Zebu Cattle"),IF(COUNTIF(lists!$M$2:$M$258, K21) > 0,"bos.indicus",IF(COUNTIF(lists!$L$2:$L$258, K21) > 0,"cross.bred","pure.bred.exotic")),"NA") -> bos.indicus | O21: Unimproved Breed | P21: NA | Q21: adult.male | R21: intensive | S21: 253.6 | T21: 118.33 | U21: 104.3 | V21: 952.7 | W21: 38.97 | X21: 563.3 | Y21: NA | Z21: NA | AA21: NA | AB21: NA | AC21: no | AD21: no
A22: BO1038 | B22: 10% treated rice offal | C22: kg/day | D22: 2.58 | E22: 0.45 | F22: 166.7 | G22: 0.29 | H22: NA | I22: 3 | J22: Cattle | K22: Bunaji | L22: =IF(OR(J22="Cattle",J22="Zebu Cattle"),IF(COUNTIF(lists!$M$2:$M$258, K22) > 0,"bos.indicus",IF(COUNTIF(lists!$L$2:$L$258, K22) > 0,"cross.bred","pure.bred.exotic")),"NA") -> bos.indicus | O22: Unimproved Breed | P22: NA | Q22: adult.male | R22: intensive | S22: 220.5 | T22: 118.84 | U22: 121.36 | V22: 951.9 | W22: 33.55 | X22: 561.5 | Y22: NA | Z22: NA | AA22: NA | AB22: NA | AC22: no | AD22: no
A23: BO1038 | B23: 15% treated rice ofall | C23: kg/day | D23: 2.81 | E23: 0.45 | F23: 175.8 | G23: 0.44 | H23: NA | I23: 3 | J23: Cattle | K23: Bunaji | L23: =IF(OR(J23="Cattle",J23="Zebu Cattle"),IF(COUNTIF(lists!$M$2:$M$258, K23) > 0,"bos.indicus",IF(COUNTIF(lists!$L$2:$L$258, K23) > 0,"cross.bred","pure.bred.exotic")),"NA") -> bos.indicus | O23: Unimproved Breed | P23: NA | Q23: adult.male | R23: intensive | S23: 208.7 | T23: 116.83 | U23: 122.85 | V23: 942.7 | W23: 36.31 | X23: 558.3 | Y23: NA | Z23: NA | AA23: NA | AB23: NA | AC23: no | AD23: no
A24: BO1038 | B24: 5% treated rice offal | C24: kg/day | D24: 2.69 | E24: 0.45 | F24: 164.9 | G24: 0.25 | H24: NA | I24: 3 | J24: Cattle | K24: Bunaji | L24: =IF(OR(J24="Cattle",J24="Zebu Cattle"),IF(COUNTIF(lists!$M$2:$M$258, K24) > 0,"bos.indicus",IF(COUNTIF(lists!$L$2:$L$258, K24) > 0,"cross.bred","pure.bred.exotic")),"NA") -> bos.indicus | O24: Unimproved Breed | P24: NA | Q24: adult.male | R24: intensive | S24: 233.6 | T24: 116.75 | U24: 116.97 | V24: 952.5 | W24: 34.2 | X24: 554.4 | Y24: NA | Z24: NA | AA24: NA | AB24: NA | AC24: no | AD24: no
A25: BO1052 | B25: 0% untreated WMV | C25: kg/day | D25: 16.7 | E25: NA | F25: NA | G25: NA | H25: 18.55 | J25: Cattle | K25: Holstien_Friesian | L25: =IF(OR(J25="Cattle",J25="Zebu Cattle"),IF(COUNTIF(lists!$M$2:$M$258, K25) > 0,"bos.indicus",IF(COUNTIF(lists!$L$2:$L$258, K25) > 0,"cross.bred","pure.bred.exotic")),"NA") -> pure.bred.exotic | O25: Improved Breeds | P25: Lactating Female | Q25: lactating.adult.female | R25: intensive | S25: 194 | T25: 98 | U25: 133 | V25: NA | W25: 29.4 | X25: 331.2 | Y25: 63.76 | Z25: NA | AA25: NA | AB25: NA | AC25: no | AD25: no
A26: BO1052 | B26: 100% treated WMV | C26: kg/day | D26: 16.3 | E26: NA | F26: NA | G26: NA | H26: 16.8 | J26: Cattle | K26: Holstien_Friesian | L26: =IF(OR(J26="Cattle",J26="Zebu Cattle"),IF(COUNTIF(lists!$M$2:$M$258, K26) > 0,"bos.indicus",IF(COUNTIF(lists!$L$2:$L$258, K26) > 0,"cross.bred","pure.bred.exotic")),"NA") -> pure.bred.exotic | O26: Improved Breeds | P26: Lactating Female | Q26: lactating.adult.female | R26: intensive | S26: 224 | T26: 98.3 | U26: 124 | V26: NA | W26: 29 | X26: 356 | Y26: 62.06 | Z26: NA | AA26: NA | AB26: NA | AC26: no | AD26: no
A27: BO1052 | B27: 25% treated WMV | C27: kg/day | D27: 16.7 | E27: NA | F27: NA | G27: NA | H27: 18.21 | J27: Cattle | K27: Holstien_Friesian | L27: =IF(OR(J27="Cattle",J27="Zebu Cattle"),IF(COUNTIF(lists!$M$2:$M$258, K27) > 0,"bos.indicus",IF(COUNTIF(lists!$L$2:$L$258, K27) > 0,"cross.bred","pure.bred.exotic")),"NA") -> pure.bred.exotic | O27: Improved Breeds | P27: Lactating Female | Q27: lactating.adult.female | R27: intensive | S27: 202 | T27: 97.9 | U27: 131 | V27: NA | W27: 29.2 | X27: 337.5 | Y27: 63.03 | Z27: NA | AA27: NA | AB27: NA | AC27: no | AD27: no
A28: BO1052 | B28: 50% treated WMV | C28: kg/day | D28: 16.6 | E28: NA | F28: NA | G28: NA | H28: 17.67 | J28: Cattle | K28: Holstien_Friesian | L28: =IF(OR(J28="Cattle",J28="Zebu Cattle"),IF(COUNTIF(lists!$M$2:$M$258, K28) > 0,"bos.indicus",IF(COUNTIF(lists!$L$2:$L$258, K28) > 0,"cross.bred","pure.bred.exotic")),"NA") -> pure.bred.exotic | O28: Improved Breeds | P28: Lactating Female | Q28: lactating.adult.female | R28: intensive | S28: 210 | T28: 99.7 | U28: 127 | V28: NA | W28: 29.1 | X28: 344.4 | Y28: 62.68 | Z28: NA | AA28: NA | AB28: NA | AC28: no | AD28: no
A29: BO1052 | B29: 75% treated WMV | C29: kg/day | D29: 16.3 | E29: NA | F29: NA | G29: NA | H29: 17.09 | J29: Cattle | K29: Holstien_Friesian | L29: =IF(OR(J29="Cattle",J29="Zebu Cattle"),IF(COUNTIF(lists!$M$2:$M$258, K29) > 0,"bos.indicus",IF(COUNTIF(lists!$L$2:$L$258, K29) > 0,"cross.bred","pure.bred.exotic")),"NA") -> pure.bred.exotic | O29: Improved Breeds | P29: Lactating Female | Q29: lactating.adult.female | R29: intensive | S29: 217 | T29: 98.3 | U29: 126 | V29: NA | W29: 29.2 | X29: 351 | Y29: 62.14 | Z29: NA | AA29: NA | AB29: NA | AC29: no | AD29: no
A30: BO1053 | B30: inoculated silage buffalo | C30: kg/day | D30: 15.99 | E30: NA | F30: NA | G30: NA | H30: 11.9 | I30: 10 | J30: Buffalo | K30: Unspecified | L30: =IF(OR(J30="Cattle",J30="Zebu Cattle"),IF(COUNTIF(lists!$M$2:$M$258, K30) > 0,"bos.indicus",IF(COUNTIF(lists!$L$2:$L$258, K30) > 0,"cross.bred","pure.bred.exotic")),"NA") -> NA | O30: Unspecified | P30: Postpartum Female | Q30: lactating.adult.female | R30: intensive | S30: NA | T30: 59.8 | U30: 251.5 | V30: 390 | W30: 4.3 | X30: NA | Y30: NA | Z30: NA | AA30: NA | AB30: NA
A31: BO1053 | B31: inoculated silage cattle | C31: kg/day | D31: 15.68 | E31: NA | F31: NA | G31: NA | H31: 27.8 | I31: 6 | J31: Cattle | K31: Unspecified | L31: =IF(OR(J31="Cattle",J31="Zebu Cattle"),IF(COUNTIF(lists!$M$2:$M$258, K31) > 0,"bos.indicus",IF(COUNTIF(lists!$L$2:$L$258, K31) > 0,"cross.bred","pure.bred.exotic")),"NA") -> bos.indicus | O31: Unspecified | P31: Postpartum Female | Q31: lactating.adult.female | R31: intensive | S31: NA | T31: 59.8 | U31: 251.5 | V31: 390 | W31: 4.3 | X31: NA | Y31: NA | Z31: NA | AA31: NA | AB31: NA | AC31: no | AD31: no
A32: BO1053 | B32: non-inoculated silage buffalo | C32: kg/day | D32: 15.21 | E32: NA | F32: NA | G32: NA | H32: 10.85 | I32: 10 | J32: Buffalo | K32: Unspecified | L32: =IF(OR(J32="Cattle",J32="Zebu Cattle"),IF(COUNTIF(lists!$M$2:$M$258, K32) > 0,"bos.indicus",IF(COUNTIF(lists!$L$2:$L$258, K32) > 0,"cross.bred","pure.bred.exotic")),"NA") -> NA | O32: Unspecified | P32: Postpartum Female | Q32: lactating.adult.female | R32: intensive | S32: NA | T32: 48.4 | U32: 82.1 | V32: 350 | W32: 19.8 | X32: NA | Y32: NA | Z32: NA | AA32: NA | AB32: NA
A33: BO1053 | B33: non-inoculated silage cattle | C33: kg/day | D33: 14.75 | E33: NA | F33: NA | G33: NA | H33: 25.5 | I33: 6 | J33: Cattle | K33: Unspecified | L33: =IF(OR(J33="Cattle",J33="Zebu Cattle"),IF(COUNTIF(lists!$M$2:$M$258, K33) > 0,"bos.indicus",IF(COUNTIF(lists!$L$2:$L$258, K33) > 0,"cross.bred","pure.bred.exotic")),"NA") -> bos.indicus | O33: Unspecified | P33: Postpartum Female | Q33: lactating.adult.female | R33: intensive | S33: NA | T33: 48.4 | U33: 82.1 | V33: 350 | W33: 19.8 | X33: NA | Y33: NA | Z33: NA | AA33: NA | AB33: NA | AC33: no | AD33: no
A34: BO1054 | B34: 0 PCK | C34: kg/day | D34: 8.4 | E34: 0.14 | F34: 247.6 | G34: 1.14 | H34: NA | I34: 4 | J34: Cattle | K34: Bunaji | L34: =IF(OR(J34="Cattle",J34="Zebu Cattle"),IF(COUNTIF(lists!$M$2:$M$258, K34) > 0,"bos.indicus",IF(COUNTIF(lists!$L$2:$L$258, K34) > 0,"cross.bred","pure.bred.exotic")),"NA") -> bos.indicus | O34: Unimproved Breed | P34: Bulls | Q34: growing.male | R34: intensive | S34: 277 | T34: 95.8 | U34: 112.3 | V34: NA | W34: 79 | X34: 444.2 | Y34: NA | Z34: NA | AA34: NA | AB34: NA | AC34: no | AD34: no
A35: BO1054 | B35: 10 PCK | C35: kg/day | D35: 8.75 | E35: 0.14 | F35: 257.9 | G35: 1.33 | H35: NA | I35: 4 | J35: Cattle | K35: Bunaji | L35: =IF(OR(J35="Cattle",J35="Zebu Cattle"),IF(COUNTIF(lists!$M$2:$M$258, K35) > 0,"bos.indicus",IF(COUNTIF(lists!$L$2:$L$258, K35) > 0,"cross.bred","pure.bred.exotic")),"NA") -> bos.indicus | O35: Unimproved Breed | P35: Bulls | Q35: growing.male | R35: intensive | S35: 307.2 | T35: 94.1 | U35: 111.94 | V35: NA | W35: 75.1 | X35: 490.6 | Y35: NA | Z35: NA | AA35: NA | AB35: NA | AC35: no | AD35: no
A36: BO1054 | B36: 20 PCK | C36: kg/day | D36: 8.2 | E36: 0.14 | F36: 253.7 | G36: 1.16 | H36: NA | I36: 4 | J36: Cattle | K36: Bunaji | L36: =IF(OR(J36="Cattle",J36="Zebu Cattle"),IF(COUNTIF(lists!$M$2:$M$258, K36) > 0,"bos.indicus",IF(COUNTIF(lists!$L$2:$L$258, K36) > 0,"cross.bred","pure.bred.exotic")),"NA") -> bos.indicus | O36: Unimproved Breed | P36: Bulls | Q36: growing.male | R36: intensive | S36: 294.7 | T36: 98.3 | U36: 136 | V36: NA | W36: 88.2 | X36: 457.8 | Y36: NA | Z36: NA | AA36: NA | AB36: NA | AC36: no | AD36: no
A37: BO1054 | B37: 30 PCK | C37: kg/day | D37: 8.49 | E37: 0.14 | F37: 256.3 | G37: 1.31 | H37: NA | I37: 4 | J37: Cattle | K37: Bunaji | L37: =IF(OR(J37="Cattle",J37="Zebu Cattle"),IF(COUNTIF(lists!$M$2:$M$258, K37) > 0,"bos.indicus",IF(COUNTIF(lists!$L$2:$L$258, K37) > 0,"cross.bred","pure.bred.exotic")),"NA") -> bos.indicus | O37: Unimproved Breed | P37: Bulls | Q37: growing.male | R37: intensive | S37: 342.9 | T37: 97.8 | U37: 131.9 | V37: NA | W37: 82.6 | X37: 552.2 | Y37: NA | Z37: NA | AA37: NA | AB37: NA | AC37: no | AD37: no
A38: BO1054 | B38: 40 PCK | C38: kg/day | D38: 8.36 | E38: 0.14 | F38: 250.8 | G38: 1.18 | H38: NA | I38: 4 | J38: Cattle | K38: Bunaji | L38: =IF(OR(J38="Cattle",J38="Zebu Cattle"),IF(COUNTIF(lists!$M$2:$M$258, K38) > 0,"bos.indicus",IF(COUNTIF(lists!$L$2:$L$258, K38) > 0,"cross.bred","pure.bred.exotic")),"NA") -> bos.indicus | O38: Unimproved Breed | P38: Bulls | Q38: growing.male | R38: intensive | S38: 381.2 | T38: 94.9 | U38: 108 | V38: NA | W38: 71.2 | X38: 563.9 | Y38: NA | Z38: NA | AA38: NA | AB38: NA | AC38: no | AD38: no
A39: BO1070 | B39: 0% V. amygdalina | C39: kg/day | D39: 0.4216 | E39: NA | F39: NA | G39: NA | H39: 3.34 | J39: Sheep | K39: Fogera | L39: =IF(OR(J39="Cattle",J39="Zebu Cattle"),IF(COUNTIF(lists!$M$2:$M$258, K39) > 0,"bos.indicus",IF(COUNTIF(lists!$L$2:$L$258, K39) > 0,"cross.bred","pure.bred.exotic")),"NA") -> NA | O39: Unimproved Breed | P39: Lactating Female | Q39: lactating.adult.female | R39: intensive | S39: NA | T39: NA | U39: NA | V39: NA | W39: NA | X39: NA | Y39: 62.76 | Z39: NA
A40: BO1070 | B40: 100% V. amygdalina | C40: kg/day | D40: 0.2664 | E40: NA | F40: NA | G40: NA | H40: 3.34 | J40: Sheep | K40: Fogera | L40: =IF(OR(J40="Cattle",J40="Zebu Cattle"),IF(COUNTIF(lists!$M$2:$M$258, K40) > 0,"bos.indicus",IF(COUNTIF(lists!$L$2:$L$258, K40) > 0,"cross.bred","pure.bred.exotic")),"NA") -> NA | O40: Unimproved Breed | P40: Lactating Female | Q40: lactating.adult.female | R40: intensive | S40: NA | T40: NA | U40: NA | V40: NA | W40: NA | X40: NA | Y40: 69.65 | Z40: NA
...

Sheet Biblio
A1: B.Code | B1: B.Author.Last | C1: B.Date | D1: B.Journal | E1: B.New | F1: B.DOI | G1: B.Url | H1: B.Project
A2: BO1030 | B2: 0 | C2: 0 | D2: 0 | E2: NA | F2: NA | G2: NA | H2: ERA 2024 Livestock
A3: 0 | B3: 0 | C3: 0 | D3: 0 | E3: NA | F3: NA | G3: NA | H3: ERA 2024 Livestock
A4: HK0005 | B4: Abasiekong | C4: 1991 | D4: Archiv Fur Tierernahrung-Archives of Animal Nutrition | E4: No | F4: 10.1080/17450399109428459 | G4: NA | H4: Livestock Update 2022
A5: JS0292 | B5: Abatan | C5: 2015 | D5: Tropical Animal Health and Production | E5: No | F5: 10.1007/s11250-014-0695-1 | G5: NA | H5: Livestock Update 2022
A6: EM1104 | B6: Abd El-Mola | C6: 2019 | D6: Egyptian Journal of Animal Production | E6: NA | F6: 10.21608/ejap.2019.93005 | G6: NA | H6: ERA 2024 Livestock
A7: JS0118 | B7: Abd El-Rahman | C7: 2011 | D7: African Journal of Biotechnology | E7: No | F7: 10.5897/AJB11.1595 | G7: NA | H7: Livestock Update 2022
A8: JO1086 | B8: Abdelazem | C8: 2019 | D8: Research Journal of Animal and Veterinary Sciences | E8: NA | F8: 10.22587/rjavs.2019.11.1.1 | G8: NA | H8: ERA 2024 Livestock
A9: EM1054 | B9: Abdel-Raheem | C9: 2021 | D9: Saudi Journal of Biological Sciences | E9: NA | F9: 10.1016/j.sjbs.2021.04.037 | G9: NA | H9: ERA 2024 Livestock
A10: EM1005 | B10: Abdel-Rahman | C10: 2019 | D10: Journal of Animal Health and Production | E10: NA | F10: 10.17582/journal.jahp/2019/7.4.131.141 | G10: NA | H10: ERA 2024 Livestock
A11: JS0123 | B11: Abdel-Shafy | C11: 2011 | D11: Tropical Animal Health and Production | E11: No | F11: 10.1007/s11250-010-9696-x | G11: NA | H11: Livestock Update 2022
A12: JS0124 | B12: Abdel-Tawwab | C12: 2009 | D12: Aquaculture Research | E12: No | F12: 10.1111/j.1365-2109.2009.02195.x | G12: NA | H12: Livestock Update 2022
A13: JS0295 | B13: Abdel-Tawwab | C13: 2015 | D13: Aquaculture | E13: No | F13: 10.1016/j.aquaculture.2015.06.010 | G13: NA | H13: Livestock Update 2022
A14: NJ0003 | B14: Abdel-Tawwab | C14: 2018 | D14: Fish & Shellfish Immunology | E14: No | F14: 10.1016/j.fsi.2018.04.057 | G14: NA | H14: Livestock Update 2022
A15: JS0125 | B15: Abdel-Warith | C15: 2001 | D15: Aquaculture Research | E15: No | F15: 10.1046/j.1355-557x.2001.00053.x | G15: NA | H15: Livestock Update 2022
... A728: LR0001 | B728: Edgem | C728: 2026 | D728: Descover Applied Science | E728: NA | F728: https://doi.org/10.1007/s42452-026-09070-6 | G728: NA | H728: CLIFF-GRADS 2026
A729: LR0002 | B729: Kitaw | C729: 2010 | D729: East African Journal of Sciences | F729: NA | G729: NA | H729: CLIFF-GRADS 2026
A730: LR0003 | B730: Mekonin | C730: 2022 | D730: Animal: The international journal of animal biosciences | F730: https://doi.org/10.1016/j.animal.2022.100632 | G730: NA | H730: CLIFF-GRADS 2026
A731: LR0004 | B731: Mideksa | C731: 2016 | D731: Journal of Biology, Agriculture and Healthcare | F731: NA | G731: NA | H731: CLIFF-GRADS 2026
A732: LR0005 | B732: Acheampong_Bateng | C732: 2008 | D732: Tropical Animal Health and Producton | F732: 10.1007/s11250-007-9076-3 | G732: NA | H732: CLIFF-GRADS 2026
A733: LR0006 | B733: Goopy | C733: 2020 | D733: British Journal of Nutrition | F733: 10.1017/S0007114519003350 | G733: NA | H733: CLIFF-GRADS 2026
A734: LR0009 | B734: Erasmus and Botha | C734: 1994 | D734: Journal of Dairy Science | F734: NA | G734: NA | H734: CLIFF-GRADS 2026
A735: LR0010 | B735: Erasums and Prinsloo | C735: 1989 | D735: Journal of Dairy Science | F735: NA | G735: NA | H735: CLIFF-GRADS 2026
A736: LR0011 | B736: Gamedze | C736: 2024 | D736: Tropical Animal Health and Producton | F736: https://doi.org/10.1007/s11250-024-04226-1 | G736: NA | H736: CLIFF-GRADS 2026
A737: LR0012 | B737: Gbenou | C737: 2024a | D737: Animal: The international journal of animal biosciences | F737: https://doi.org/10.1016/j.animal.2024.101320 | G737: NA | H737: CLIFF-GRADS 2026
A738: LR0013 | B738: Gbenou | C738: 2024b | D738: Archives of Animal Nutrition | F738: https://doi.org/10.1080/1745039X.2024.2356326 | G738: NA | H738: CLIFF-GRADS 2026
A739: LR0014 | B739: Gbenou | C739: 2025 | D739: Veterinary and Animal Science | F739: https://doi.org/10.1016/j.vas.2025.100511 | G739: NA | H739: CLIFF-GRADS 2026
A740: LR0015 | B740: Gebrehawariat | C740: 2010 | D740: Tropical Animal Health and Producton | F740: 10.1007/s11250-010-9623-1 | G740: NA | H740: CLIFF-GRADS 2026
A741: LR0016 | B741: Kekana | C741: 2021a | D741: Journal of Dairy Science | F741: https://doi.org/10.3168/jds.2021-21535 | G741: NA | H741: CLIFF-GRADS 2026
A742: LR0017 | B742: Madziga | C742: 2026 | D742: Tropical Animal Health and Producton | F742: https://doi.org/10.1007/s11250-026-04974-2 | G742: NA | H742: CLIFF-GRADS 2026
A743: LR0018 | B743: Mekcha | C743: 2026 | D743: Scientific Report | F743: https://doi.org/10.1038/s41598-026-52674-6 | G743: NA | H743: CLIFF-GRADS 2026
A744: LR0019 | B744: Girmaud | C744: 1998 | D744: Animal Science | F744: NA | G744: http://journals.cambridge.org/abstract_S1357729800009784 | H744: CLIFF-GRADS 2026
A745: LR0020 | B745: Ngxumeshe | C745: 2025 | D745: Animals | F745: https://doi.org/10.3390/ani15172505 | G745: NA | H745: CLIFF-GRADS 2026
A746: LR0021 | B746: Rabatseta | C746: 2024 | D746: Tropical Animal Health and Producton | F746: https://doi.org/10.1007/s11250-024-03959-3 | G746: NA | H746: CLIFF-GRADS 2026
A747: LR0022 | B747: Shipandeni | C747: 2023 | D747: Journal of Animal Science | F747: https://doi.org/10.1093/jas/skad147 | G747: NA | H747: CLIFF-GRADS 2026
A748: LR0023 | B748: Slayi | C748: 2025 | D748: Frontiers in Veterinary Science | F748: 10.3389/fvets.2025.1513368 | G748: NA | H748: CLIFF-GRADS 2026
A749: LR0024 | B749: Smith | C749: 2006 | D749: Tropical Animal Health and Producton | F749: 10.1007/s11250-006-4342-3 | G749: NA | H749: CLIFF-GRADS 2026
A750: LR0025 | B750: Tayengwa | C750: 2020 | D750: Meat Science | F750: https://doi.org/10.1016/j.meatsci.2019.107969 | G750: NA | H750: CLIFF-GRADS 2026
A751: LR0026 | B751: Tayengwa | C751: 2021 | D751: Animal: The international journal of animal biosciences | F751: https://doi.org/10.1016/j.animal.2020.100020 | G751: NA | H751: CLIFF-GRADS 2026
A752: LR0027 | B752: van Wynagaard | C752: 2018 | D752: Journal of Dairy Science | F752: https://doi.org/10.3168/jds.2017-14327 | G752: NA | H752: CLIFF-GRADS 2026
...

Sheet lists
A1: Stages | B1: Production.systems | D1: All.breeds.sheep | E1: All.breeds.goat | F1: All.breeds.cattle | G1: Sheep.crossbred | H1: Sheep.indigenous | I1: Goats.crossbred | J1: Goats.indigenous | K1: Cattle.purebred.exotic | L1: Cattle.crossbred | M1: Cattle.bos.indicus | O1: grazing | P1: marker.method
A2: gestating.adult.female | B2: extensive | D2: {=_xlfn.UNIQUE(_xlfn._xlws.FILTER(feed_intake_raw!K2:K2978,feed_intake_raw!J2:J2978="Sheep"))} -> Unspecified | E2: {=_xlfn.UNIQUE(_xlfn._xlws.FILTER(feed_intake_raw!K2:K2978,feed_intake_raw!J2:J2978="Goat"))} -> West African Dwarf | F2: {=_xlfn.UNIQUE(_xlfn._xlws.FILTER(feed_intake_raw!K2:K2978,OR(feed_intake_raw!J2:J2978="Cattle",feed_intake_raw!J2:J2978="Zebu Cattle")))} -> Ankole Longhorn***Holstein Friesian | H2: Barki | J2: West African Dwarf | K2: Holstein-Friesian | L2: Ankole Longhorn***Holstein Friesian | M2: Zebu | O2: yes | P2: yes
A3: lactating.adult.female | B3: semi.intensive | D3: Fogera | E3: Abergelle | F3: Unspecified | J3: Red Sokoto | K3: Jersey | L3: Unspecified Crossbreed | M3: Unspecified | O3: no | P3: no
A4: non.gestating.adult.female | B4: intensive | D4: Barki | E4: Saanen | F4: Holstien_Friesian | K4: Simmental | L4: Arsi-Frisian cross | M4: Bunaji
A5: adult.male | D5: West African Dwarf | E5: Boer | F5: Unspecified Crossbreed | K5: Sussex red | L5: Friesian x Ankole crossbred | M5: Fogera
A6: adult.female | D6: Yankasa | E6: Unspecified | F6: Bunaji | K6: Hereford | L6: Arsi-Frisian cross | M6: Azawak
A7: adult.all | D7: Farta | E7: Arsi Bale | F7: Fogera | K7: Aberdeen Angus | L7: Friesian x Bunaji | M7: Borana & Arsi
A8: weaner | D8: Blackhead Ogaden | E8: Damascus | F8: Begaria | K8: Friesian and Ayrshire | L8: Holstein Friesian x Zebu (Arado) crossbred | M8: Zebu (Malawi )
A9: growing.male | D9: Dorper | E9: 55% Kamorai***30% Boer***15% East African indigenous | F9: Zebu | K9: Angus | L9: Boran x Friesian crossbred | M9: Horro
A10: growing.female | D10: Tigray Highland | E10: Zaraibi | F10: Horro | K10: Friesian***Ayrshire | L10: Holstein-Mashona crossbred | M10: Zebu (Ethiopia)
A11: growing.all | D11: Hararghe Highland | E11: Local Variety | F11: Rahaji | K11: Brown Swiss | L11: Boran x Friesian crossbred | M11: Harar
A12: adult.male.castrate | D12: Ossimi | E12: Woyto-Guji | F12: Friesian***Bunaji | K12: Baoule breed_B. taurus | L12: Friesian x Boran crossbred, | M12: Sudanese Fulani zebu
A13: growing.male.castrate | D13: Finn***Ossimi | E13: Pedi | F13: Azawak | K13: Holstein_Friesian | L13: Holstein-Friesian x Zebu crossbred | M13: Borana
A14: NA | D14: Horro | E14: Small East African | F14: Holstein***Friesian***Arsi | L14: 75% Friesian-Borana crossbred | M14: Horro
D15: Gumuz | E15: Somali | F15: Holstein***Friesian***Zebu | L15: Holstein Friesian x Boran | M15: Borana
D16: Oudah Rams | E16: Boer***Damascus | F16: Friesian x Baladi | L16: Bonsmara | M16: Bunaji
D17: Local Variety | E17: Red Sokoto | F17: Jersey | L17: Nguni * Bonsmara cross | M17: Rahaji
D18: 25% Dorper | E18: Central Highland | F18: Nguni | L18: Friesian x Boran | M18: Sokoto Gudali
D19: Timahdite | E19: Mashona Does | F19: Ankole***Friesian | L19: Bonsmara breed & Simmentaler x Beefmaster cross | M19: Sokoto
D20: Farafra | E20: 0% Kamorai***0% Boer***0% Small East African | F20: Friesian***Borana cross | L20: Boran x Friesian F1 | M20: Bunaji-Sokoto
D21: Arsi-bale | E21: Boran | F21: Tanzania Shorthorn Zebu | L21: Local x Holstein Friesian | M21: Tanzanian Short Horn Zebu
D22: Abergelle | E22: West African Long-legged | F22: 75% Friesian***25% Boran | L22: Crossbred | M22: Nguni
D23: Wogera | E23: NA | F23: Local Breeds Unspecified | L23: Boran X Friesian | M23: Tanzania_shorthorn zebu
D24: Doyogena | E24: Kamorai (0.55)***Boer (0.3)***East African indigenous (0.15) | F24: N'Dama | L24: Mixed breed | M24: Borgou
D25: Washera | E25: Small East African***Norwegian | F25: Sudan Baggara | L25: Holstein Friesian-Arsi cross | M25: Tanzanian Shorthorn Zebu
D26: Sardi | E26: Norwegian landrace***Local Tanzania cross breed | F26: Mpwapwa | L26: Friesian–Boran crossbred | M26: Bunaji
... D41: West African Djallonke | E41: Short-eared Somali | F41: Saanen | L41: Friesian x Boran crossbred | M41: Nguni
D42: Sudan Desert | F42: Boer | L42: Boran x Friesian/Jersey | M42: Tanzania Shorthorn Zebu
D43: Red Maasai | F43: Arsi Bale | L43: Mpwapwa/Mpwapwa crossbred | M43: Local Breeds Unspecified
D44: Ethiopian Menz | F44: Damascus | L44: Holstien * Borana cross | M44: N'Dama
D45: Arsi | F45: 55% Kamorai***30% Boer***15% East African indigenous | L45: Bos taurus x Bos indicus | M45: Sudan Baggara
D46: Simada | F46: Zaraibi | L46: Indigenous * exotics cross | M46: Mpwapwa
D47: Ethiopian Highland | F47: Local Variety | L47: Unspecified Crossbreed | M47: White Fulani
D48: Afar | F48: Woyto-Guji | L48: Holstein***Friesian***Arsi | M48: Hararghe highland
D49: South African Mutton Merino | F49: Pedi | L49: Holstein***Friesian***Zebu | M49: Peuhl Zebu cattle
D50: Kirdi | F50: Small East African | L50: Friesian x Baladi | M50: N'Dama
D51: Highland | F51: Somali | L51: Friesian***Borana cross | M51: Sudan Baggara
D52: Mutton Merino | F52: Boer***Damascus | L52: 75% Friesian***25% Boran | M52: Sahiwal
D53: Local Highland | F53: Red Sokoto | L53: Hereford***Sussex
D54: Oudah Bicolour | F54: Central Highland | L54: Bos indicus***Bos taurus
...

Sheet variable_coverage
A1: Variable | B1: Coverage_%
A2: A.Level.Name | B2: 99.941383
A3: feed_intake_unit | B3: 100
A4: feed_intake_value | B4: 100
A5: feed_intake_error | B5: 80.187573
A6: bw_kg | B6: 54.161782
A7: adg_g_day | B7: 57.385698
A8: milk_kg_day | B8: 9.96483
A9: T.Animals | B9: 98.358734
A10: Species | B10: 98.76905 | G10: =472/54 -> 8.7407407
A11: Variety | B11: 99.589683 | G11: =369.34/61 -> 6.0547541
A12: P.Practice | B12: 99.82415
A13: Stage | B13: 26.025791
A14: ADF_nutrition | B14: 26.846424
A15: ADL_nutrition | B15: 12.719812
A16: Ash_nutrition | B16: 34.173505
A17: CF_nutrition | B17: 1.1137163
A18: CFbr_nutrition | B18: 9.144197
A19: CFibre_nutrition | B19: 17.878077
A20: CH_nutrition | B20: 1.7584994
A21: CN_nutrition | B21: 0
A22: CP_nutrition | B22: 49.47245
A23: CT_nutrition | B23: 0.46893318
... A104: Protein_digest | B104: 1.4654162
